[2023-10-11T17:10:53.826+0000] {taskinstance.py:1157} INFO - Dependencies all met for dep_context=non-requeueable deps ti=<TaskInstance: wikipedia_etl.raw manual__2023-10-11T17:10:52.574562+00:00 [queued]>
[2023-10-11T17:10:53.832+0000] {taskinstance.py:1157} INFO - Dependencies all met for dep_context=requeueable deps ti=<TaskInstance: wikipedia_etl.raw manual__2023-10-11T17:10:52.574562+00:00 [queued]>
[2023-10-11T17:10:53.832+0000] {taskinstance.py:1359} INFO - Starting attempt 1 of 3
[2023-10-11T17:10:53.844+0000] {taskinstance.py:1380} INFO - Executing <Task(PythonOperator): raw> on 2023-10-11 17:10:52.574562+00:00
[2023-10-11T17:10:53.849+0000] {standard_task_runner.py:57} INFO - Started process 1273 to run task
[2023-10-11T17:10:53.852+0000] {standard_task_runner.py:84} INFO - Running: ['***', 'tasks', 'run', 'wikipedia_etl', 'raw', 'manual__2023-10-11T17:10:52.574562+00:00', '--job-id', '10', '--raw', '--subdir', 'DAGS_FOLDER/wikipedia_etl.py', '--cfg-path', '/tmp/tmpc845kdy6']
[2023-10-11T17:10:53.854+0000] {standard_task_runner.py:85} INFO - Job 10: Subtask raw
[2023-10-11T17:10:53.900+0000] {task_command.py:415} INFO - Running <TaskInstance: wikipedia_etl.raw manual__2023-10-11T17:10:52.574562+00:00 [running]> on host 8294e6c9f0c9
[2023-10-11T17:10:53.967+0000] {taskinstance.py:1660} INFO - Exporting env vars: AIRFLOW_CTX_DAG_OWNER='***' AIRFLOW_CTX_DAG_ID='wikipedia_etl' AIRFLOW_CTX_TASK_ID='raw' AIRFLOW_CTX_EXECUTION_DATE='2023-10-11T17:10:52.574562+00:00' AIRFLOW_CTX_TRY_NUMBER='1' AIRFLOW_CTX_DAG_RUN_ID='manual__2023-10-11T17:10:52.574562+00:00'
[2023-10-11T17:10:53.969+0000] {taskinstance.py:1935} ERROR - Task failed with exception
Traceback (most recent call last):
  File "/home/airflow/.local/lib/python3.8/site-packages/airflow/operators/python.py", line 192, in execute
    return_value = self.execute_callable()
  File "/home/airflow/.local/lib/python3.8/site-packages/airflow/operators/python.py", line 209, in execute_callable
    return self.python_callable(*self.op_args, **self.op_kwargs)
  File "/opt/airflow/dags/wikipedia_etl.py", line 38, in raw
    processing_date = {{ ds }}
NameError: name 'ds' is not defined
[2023-10-11T17:10:53.976+0000] {taskinstance.py:1398} INFO - Marking task as UP_FOR_RETRY. dag_id=wikipedia_etl, task_id=raw, execution_date=20231011T171052, start_date=20231011T171053, end_date=20231011T171053
[2023-10-11T17:10:53.988+0000] {standard_task_runner.py:104} ERROR - Failed to execute job 10 for task raw (name 'ds' is not defined; 1273)
[2023-10-11T17:10:54.025+0000] {local_task_job_runner.py:228} INFO - Task exited with return code 1
[2023-10-11T17:10:54.044+0000] {taskinstance.py:2776} INFO - 0 downstream tasks scheduled from follow-on schedule check
