[2023-10-11T14:45:14.988+0000] {taskinstance.py:1157} INFO - Dependencies all met for dep_context=non-requeueable deps ti=<TaskInstance: wikipedia_etl.raw manual__2023-10-11T14:45:11.985139+00:00 [queued]>
[2023-10-11T14:45:14.996+0000] {taskinstance.py:1157} INFO - Dependencies all met for dep_context=requeueable deps ti=<TaskInstance: wikipedia_etl.raw manual__2023-10-11T14:45:11.985139+00:00 [queued]>
[2023-10-11T14:45:14.997+0000] {taskinstance.py:1359} INFO - Starting attempt 1 of 3
[2023-10-11T14:45:15.009+0000] {taskinstance.py:1380} INFO - Executing <Task(PythonOperator): raw> on 2023-10-11 14:45:11.985139+00:00
[2023-10-11T14:45:15.014+0000] {standard_task_runner.py:57} INFO - Started process 80 to run task
[2023-10-11T14:45:15.017+0000] {standard_task_runner.py:84} INFO - Running: ['***', 'tasks', 'run', 'wikipedia_etl', 'raw', 'manual__2023-10-11T14:45:11.985139+00:00', '--job-id', '3', '--raw', '--subdir', 'DAGS_FOLDER/wikipedia_etl.py', '--cfg-path', '/tmp/tmpq_swu4zp']
[2023-10-11T14:45:15.020+0000] {standard_task_runner.py:85} INFO - Job 3: Subtask raw
[2023-10-11T14:45:15.063+0000] {task_command.py:415} INFO - Running <TaskInstance: wikipedia_etl.raw manual__2023-10-11T14:45:11.985139+00:00 [running]> on host 677b8d627291
[2023-10-11T14:45:15.131+0000] {taskinstance.py:1660} INFO - Exporting env vars: AIRFLOW_CTX_DAG_OWNER='***' AIRFLOW_CTX_DAG_ID='wikipedia_etl' AIRFLOW_CTX_TASK_ID='raw' AIRFLOW_CTX_EXECUTION_DATE='2023-10-11T14:45:11.985139+00:00' AIRFLOW_CTX_TRY_NUMBER='1' AIRFLOW_CTX_DAG_RUN_ID='manual__2023-10-11T14:45:11.985139+00:00'
[2023-10-11T14:45:15.132+0000] {taskinstance.py:1935} ERROR - Task failed with exception
Traceback (most recent call last):
  File "/home/airflow/.local/lib/python3.8/site-packages/airflow/operators/python.py", line 192, in execute
    return_value = self.execute_callable()
  File "/home/airflow/.local/lib/python3.8/site-packages/airflow/operators/python.py", line 209, in execute_callable
    return self.python_callable(*self.op_args, **self.op_kwargs)
  File "/opt/airflow/dags/wikipedia_etl.py", line 37, in raw
    processing_date = date.today().strftime("%Y-%m-%d")
UnboundLocalError: local variable 'date' referenced before assignment
[2023-10-11T14:45:15.139+0000] {taskinstance.py:1398} INFO - Marking task as UP_FOR_RETRY. dag_id=wikipedia_etl, task_id=raw, execution_date=20231011T144511, start_date=20231011T144514, end_date=20231011T144515
[2023-10-11T14:45:15.154+0000] {standard_task_runner.py:104} ERROR - Failed to execute job 3 for task raw (local variable 'date' referenced before assignment; 80)
[2023-10-11T14:45:15.190+0000] {local_task_job_runner.py:228} INFO - Task exited with return code 1
[2023-10-11T14:45:15.209+0000] {taskinstance.py:2776} INFO - 0 downstream tasks scheduled from follow-on schedule check
